Workbook

Sheet Racional
A1: Referencia colores solapas
A2: Solapas financieras
A3: Soalapas auxiliares para dashboard
A4: Solapas económicas
A5: Tablas Dinámicas
A6: Mark Up
A7: Información extra que alimenta fórmulas
A11: Fecha del mes aprox | B11: Proceso General | C11: Tarea | D11: Repsonsables | E11: Solapa a completar/Usar | F11: TD o Solapa que se actualiza automáticamente
A12: Entre el 25/26 de cada mes | B12: Cierre de mes equipo | C12: Se le pide al equipo que cargue horas en Asana tanto del mes que hayan quedado pendientes como las estimadas de los días laborables que quedan. | D12: Vicky Puri / Vicky Acha | E12: N/A | F12: N/A
A13: Entre el 25/26 de cada mes | B13: Cierre de mes equipo | C13: Se crean los proyectos nuevos en Abejita. | D13: Vicky Puri / Vicky Acha | E13: N/A | F13: N/A
A14: Entre el 27/28 de cada mes | B14: Cierre de mes equipo | C14: Completar el cierre de horas mensual en base a las horas cerradas en Asana. Se completa la solapa con la información: Detalle COL A (nombre de la persona. Si no aparace se debe deseocultar la solapa Listas y sumar el nombre de la persona) Subtipo de Costo COL B (automatizada, si no aparece info se deba deseocultar la solapa Clasificaciones y sumar la variable que no tiene información) Mes COL C y Año COL D Tipo de costo COL E (Directo si está asociado a cliente dierto indirecto si es Epical general o Demo) Nro Proyecto COL G (ver fila 16) Tipo de proyecto COL H (Fee, One Shot, Epical para general y Demo si es cliente Epical pero refiere a una demo) Proyecto COL I (si un proyecto está en varios meses siempre mantener el mismo nombre. Si es nuevo se pone un referenica general de lo que es) Cliente COL J (en caso que sea Epical se selecciona Epical) Cantidad de horas Objetivo COL K (se saca de la solapa Horas Asignadas) Cantidad de horas reales Asana COL L (se carga específicamente lo que aparece en Asana indepedientemente si es más o menos de lo que debe trabajar la persona. Por ejemplo si una persona debería completar 160 horas pero completa 150 se cargan las 150) Cantidad de horas para facutración COL M (se carga lo de Asana pero si es necesario se redondea con Epical para arriba o para abajo. Sobre esta columna se calcula el monto a facurar) | D14: Vicky Puri / Vicky Acha | E14: Costos directos e indirectos | F14: TD Costos Directos para CIERRE TD Costos para seguimiento MARKUP
A15: Entre el 27/28 de cada mes | B15: Cierre de mes equipo | C15: Se completan los archivos de honorarios. 1- En caso de ser variables y que cobren una parte en USD se completa en la solapa Hoja 1 la diferencia de horas vs lo que se hizo en el cierre parcial. 2- En caso de ser variables y que cobren todo en ARS se completa en la solapa Hoja 1 el total de horas a facturar. 3- En todos los casos se completa la solapa Control Abejita con la apertura que deben usar para cargar la información en la misma. Para esto, se filtra por persona la TD CIERRE POR CUENTA Y PERSONA y se va copiando y pegando la distribución en cada archivo de honorarios. | D15: Vicky Puri / Vicky Acha | E15: TD Costos Directos para CIERRE Archivos de honorarios de cada persona | F15: N/A
A16: A fin de mes, antes que termine | B16: Cierre de mes equipo | C16: Hacer la carga de información en Abejita para que el equipo pueda cargar las horas. | D16: Michelle | E16: N/A | F16: N/A
A17: Entre el 30/31 de cada mes | B17: Cierre de mes equipo | C17: Una vez que estan cargados los Nros de proyectos en Abejita, se pasan a la solapa Costos Directos e Indirectos en COL G | D17: Vicky Puri / Vicky Acha | E17: Costos directos e indirectos | F17: TD Costos Directos para CIERRE TD Costos para seguimiento MARKUP
A18: Todos los lunes/martes de cada semana | B18: Semanal: Carga Activo | C18: CLIENTES A COBRAR Se mantiende actualizado lo facturado completando Fecha Facturación, Nro de Factura/Comprobante, Razón Social/Cliente, Detalle, Fecha de vencimiento, Moneda original ARS, Moneda original USD. Las columnas con letra en ROJO están automatizadas. Las columnas Cobrado/No Cobrado AL CIERRE y Fecha de pago/Nota de credito se van actualizando en la medida que se pague dentro del mes la factura emitida. Es decir si estamos en agosto y se cobró en agosto, se pone SI en Cobrado/No Cobrado AL CIERRE y se completa la Fecha de Pago/Nota de crédito. | D18: Michelle | E18: Activo | F18: Resumen ejecutivo
A19: Todos los lunes/martes de cada semana | B19: Semanal: Carga Pasivo | C19: Se mantiene actualizado semanalmente los gastos que ingresan. Las columnas a completar son: Detalle, Mes, Año, Fecha de Emisión, Concepto/Detalle, Descripción/Factura, Fecha de vencimiento, Moneda original ARS, Moneda original USD. Las columnas con letrra en ROJO están automatizadas. Las columnas Pagado/No Pagado AL CIERRE y Fecha de pago se van actualizando en la medida que se pague dentro del mes la factura emitida. Es decir si estamos en agosto y se cobró en agosto, se pone SI en Pagado/No Pagado AL CIERRE y se completa la Fecha de Pago. | D19: Michelle | E19: Pasivo | F19: Resumen ejecutivo
A20: Todos los lunes/martes de cada semana | B20: Semanal: Carga Cashflow | C20: Se mantiene actualizado semanalmente los ingresos y egresos de las cuentas USA, ARG y Caja si hubiera. Las columnas con letra en ROJO están automatizadas. En caso que se cargue monton en ARS (COL I), la cotización se trae automaticamente pero es posible que el cálculo en USD (COL K) haya que calcularlos dividiendo COL I / COL J. | D20: Michelle | E20: Cashflow | F20: Resumen ejecutivo
A21: 30/31 de cada mes | B21: Cierre de mes financiero: USD | C21: Se carga el tipo de cambio BLUE del día que cierra el mes. En la solapa Info Tipo de Cambio y REM, a partir de celda A23. | D21: Michelle / Vicky Puri / Vicky Acha | E21: Info Tipo de Cambio y REM = a partir de celda A23. | F21: Todas las solapas Verdes y Naranjas, en consecuencia todas las solapas Rosas, Azules y Amarillas
A22: Entre el 1 y el 10 de cada mes | B22: Cierre de mes financiero: Cashflow | C22: Verificar que todo esté ok para poder sacar los Saldos para el Activo. | D22: Michelle | E22: Cashflow | F22: Resumen Ejecutivo
A23: Entre el 1 y el 10 de cada mes | B23: Cierre de mes financiero: Activo | C23: a) Revisión que todo esté bien cargado. La columna Cobrado/No Cobrado AL CIERRE (COL F) se actualiza para el cierre: 1- Verificar que los valores si/no estén actualizados al momento de cierre en el mes en curso. ¿Qué se cobro y qué no?. Si es SI se actualiza la fecha de cobro. 2- Verificar si hay deudas en el pasado con NO que fueron pagadas en el mes que se está cerrando. Si es SI NO SE MODIFICA LA COLUMNA COBRADO/NO COBRADO AL CIERRE (COL F), queda en NO siempre y se carga solo la fecha de cobro Fecha de pago/Nota de credito (COL G). Esto es para no se rompan los resultados del pasado. A modo informativo: todo lo que dice NO en el pasado y NO tiene fecha de cobro o tiene fecha posterior al cierre de cada mes, se contempla como parte de Clientes a Cobrar en el resumen ejecutivo. b) ACTIVO LIQUIDO SALDOS Se sacan de la solapa Cashflow, con el último dato disponible a la fecha de cierre en las columnas -SALDO SANTANDER (COL L) se carga en pesos en Activo y el Concepto/Banco es Santander-Galicia-Nación -SALDO BOA (COL M) se carga en usd en Activo y el Concepto/Banco es Bank of America. -SALDO CAJA (COL N), si hubiera se carga en la monea correspondiente en Activo y el Concepto/Banco es Caja. c) MEDIANO PLAZO CRYPTO Lo comparte Gastón y se carga como Otras Inversiones en COL A. d) ACTIVO LIQUIDO TRANSFERWISE Se carga como Transferwise en COL A | D23: Michelle a) b) d) Gastón pasa el dato de c) y lo carga Michelle | E23: Activo | F23: Resumen ejecutivo
A24: Entre el 1 y el 10 de cada mes | B24: Cierre de mes financiero: Pasivo | C24: Revisión que todo esté bien cargado. La columna Pagado/No Pagado AL CIERRE (COL E) se actualiza para el cierre: 1- Verificar que los valores si/no estén actualizados al momento de cierre en el mes en curso. ¿Qué se pagó y qué no?. Si es SI se actualiza la fecha de cobro. 2- Verificar si hay deudas en el pasado con NO que fueron pagadas en el mes que se está cerrando. Si es SI NO SE MODIFICA LA COLUMNA PAGADO/NO PAGADO AL CIERRE (COL E), queda en NO siempre y se carga solo la fecha de cobro nada más Fecha de pago (COL F). Esto es para no se rompan los resultados del pasado. A modo informativo: todo lo que dice NO en el pasado y NO tiene fecha de cobro o tiene fecha posterior al cierre de cada mes, se contempla como parte de Deugas a Pagar en el resumen ejecutivo. | E24: Pasivo | F24: Resumen Ejecutivo
A25: Ultima semana del mes | B25: Cierre de mes económico: Costos Estimados | C25: Se validan los costos estimados para actualizar en caso de ser necesario. Además se pasa lo que es el cierre de mes actual a Pasado en COL M, es decir si estamos cerrando Agosto, ese mes se pone como Pasado. Además se cargan los impuestos en ARS estimados (IVA e IIBB), que se sacan de la solapa TD Proyectos Confirmados y Estimados. Se toman solo los meses futuros. LINK A LA TD. | D25: Vicky Puri / Vicky Acha | E25: Costos estimados | F25: TD Costos Estimados para proyección Seguimiento Mark Up General los meses proyectados
A26: Ultima semana del mes | B26: Cierre de mes económico: Proyectos confirmados y Estimados | C26: Se validan los proyectos confirmados y estimados para actualizar en caso de ser necesario. Los proyectos se plasman sin IVA. Sin embargo cualquier actualización en los estimados en PESOS va a tener repercusión en la TD de impiestos mencionada en el punto anterior y debe actualizarse los costos estimados. | D26: Vicky Puri / Vicky Acha | E26: Proyectos confirmados y estimados | F26: TD Proyectos Confirmados y Estimados
A27: Primera semana del mes | B27: Cierre de mes económico: Costos Directos e Indirectos | C27: Traslado de costos pasivo: Una vez que Michelle confirma que el pasivo está actualziado, se trasadan los costos directos e indirectos del mes que se cierra a la solapa Costos Directos e Indirectos. | D27: Vicky Puri / Vicky Acha | E27: Costos directos e indirectos | F27: TD Costos para seguimiento MARKUP
A28: Primera semana del mes | B28: Cierre de mes económico: Seguimiento Mark Up General | C28: Esta solapa se divide en 3 partes señalizadas en Azul Marino: RESULDATOS - INCLUYEN TODOS LOS COSTOS y VENTAS (SIN IVA) 1- Costos directos e indirectos: se utiliza la tabla dinámica TD Costos para Seguimiento MarkUp para poder actualizar el dato del mes que se está cerrando. En esa TD se filtra el mes que se cierra y se copian y pegan todos los costos. También se puede hacer un BUSCARV para que traiga la información. Es sumamente importante chequear que el total que suma en en Seguimiento MarkUp coincida con el total que se suma en la TD. Para esto debajo de la tabla de costos hay una zona en rojo que permite copiar y pegar totales de la TD para hacer un control. LINK A LA TD UTILIZADA 2- Proyectos Confirmados y Estimados: se utiliza la TD Proyectos confirmados y estimados para poder actualizar el dato del mes que se está cerrando y las estimaciones. La carga de información en MarkUp General está automatizada, sin embargo se debe hacer el control totalizador en ROJO por si hay diferencias, se agregan nuevos clientes y hay que ajustar el BuscarV, o cualquier diferencia o ajuste que se haga. 3- Completando esta información se actualizan los resultados pero siempre es importante validar que estén ok y no haya moviemiento de celdas con los ajustes. ARR VENTAS: SE CONSIDERAN LAS VENTAS CONFIRMADAS 100%: se sacan de la solapa TD Proyectos confirmados y estimados. LINK A LA TD UTILIZADA COSTOS: SE CONSIDERAN COSTOS FIJOS, SIN LOS BONOS Y LOS PERFILES EXTRAS. SIN IMPUESTOS ARG USA. SIN INTERESES. Se sacan de la solapa TD Costos Estimados. LINK A LA TD UTILIZADA TABLA PROYECCIONES VENTAS USD Y ARS EN USD CON IVA PARA ESTADO DE SITUACIÓN 60 DÍAS Solo se ponen las ventas dado que los costos salen de la tabla de resultado. En este caso para el estado de situacion si se considera el IVA en las ventas en ARS por eso se arma una nueva tabla. Para esto se utiliza la solapa TD Proyectos confirmados y Estimados. LINK A LA TD UTILIZADA | D28: Vicky Puri / Vicky Acha | E28: Seguimiento MarkUp General | F28: N/A
A29: Primera semana del mes | B29: Cierre de mes económico: MarkUp Clientes | C29: Una vez que están cerradas la solapa Costos Directos e Indirectos, desde la solapa TD Costos Directos para CIERRE usando esta Tabla Dinámica se sacan los datos de equipo para poder estimar el MarkUp del mes de cada cliente tanto proyecto Fee como One shot on going. ¿Cómo usar? Todos los meses, una vez que se actualiza la información para le cierre se presiona en el lapiz (editar) y en filtros > Mes se elige el que se está cerrando y se elige cliente por cliente para ver las horas consumidas por cliente. Esa información se traslada luego a las solapas de MarkUp por cliente | D29: Vicky Puri / Vicky Acha | E29: Seguimiento MarkUp Cliente | F29: N/A
A30: Mitad de mes | B30: Actualización Valor Hora Real y Estimada | C30: A mitad de mes, se valida con Vicky Puricelli los ajustes pautados para poder aplicar el % real. | D30: Vicky Puri / Vicky Acha | E30: Valor Hora Real y Estimada | F30: Costos Directos e indirectos Costos Estimados TD Costos Directos para CIERRE TD Costos para seguimiento MARKUP TD Costos Estimados para proyección
A31: Principio de mes | B31: Actualización Info Tipo de Cambio y REM | C31: Una vez que el BCRA hace la publicación del informe REM se actualiza el tipo de cambio futuro, idealmente antes de enviar el cierre de mes financiero. Se realiza la carga a partir del mes siguiente al mes que se está cerrando. Es decir si se está cerrando agosto se carga las estimaciones para Septiembre, Octubre, Noviembre y Diciembre. | D31: Vicky Acha | E31: Info Tipo de Cambio y REM | F31: Todas las solapas Verdes y Naranjas, en consecuencia todas las solapas Rosas, Azules y Amarillas
A32: Principio de mes | B32: Actualización Pasivos [aux] | C32: A principio de mes, se debe agregar la formula actualizada a todos los subtipos de pasivos del mes cerrado anterior. Esto se hace copiando y pegando la formula del mes anterior, modificando todos los "FIN.MES" para que el mes sea el correcto (2025;9;1= septiembre), también hay que copiar y pegar dos lineas extra donde se tome el mes que sea esta cerrando (ej:+ SUMAR.SI.CONJUNTO(Pasivo!N:N;Pasivo!B:B;A163 ;Pasivo!E:E;"No Pagado";Pasivo!C:C; " MES QUE DESEA CERRAR Pasivo!F:F;"") +SUMAR.SI.CONJUNTO(Pasivo!N:N;Pasivo!B:B;A163 ;Pasivo!E:E;"No Pagado";Pasivo!C:C; " MES QUE DESEA CERRAR ";Pasivo!F:F; ">"&FIN.MES(FECHA(2025;MES QUE DESEA CERRAR;1);0)) Una vez que queda la formula terminada en el primer subtipo, se puede arrastrar formula | D32: Mati Gonzalez | E32: Pasivos [aux] | F32: N/A
A33: Principio de mes | B33: Actualización Activos [aux] | C33: Proceso similar al de Pasivos [aux], pero solo con "clientes a cobrar", el resto es un sumar si conjunto clasico | D33: Mati Gonzalez | E33: Activos [aux] | F33: N/A
A34: Principio de mes | B34: Rendimiento Cliente | C34: Hay quecopiar de todas las solapas de "Seguimiento markup" de clientes en especifico (no del general), la facturación y el costo de los clientes que tuvieron actividad el mes que se esta cerrando y pegarlo en rendimiento cliente | D34: Mati Gonzalez | E34: Rendimiento Cliente | F34: N/A
A35: Principio de mes | B35: Proyección [Total] | C35: Es para una cuestión estetica del dashboard. El último mes cerrado se repite dos veces (una como poryección y otra real) para unir una recta. Cuando se cierra un mes, se debe borrar la fila del mes anterior a ese queesta clasificado como proyeccion y copiar otra fila del mes que se esta cerrando como real. Las formulas de todas las columnas que se aplica ambas filas (tanto el de proyeccion como el real del mes repetido) tiene que ser arrastrada con la formula del real (de arriba para abajo) | D35: Mati Gonzalez | E35: Proyección [Total] | F35: N/A
A38: ENERO ajustar todo 2025 como valor y adaptar las nuevas tablas para 2026
C44: Responsables | D44: Periodicidad de carga | E44: Notas y comentarios
A45: Activo | C45: Lorena y Michelle general Tonga Otras Inversiones Mediano Plazo (cripto) | D45: Semanal con cierre completo al último día del mes. | E45: -Las columnas con fondo gris en el encabezado solo se completan si el Concepto/Banco es "Deuda clientes". -Las columnas con letra en rojo están automatizadas -Al cierre del mes Tonga completa Otras Inversiones Mediano Plazo (cripto) -Al cierre del mes Michelle completa los saldos disponibles / activos líquidos en Santander-Galicia-Nación, Bank Of America, Transferwise que salen del cashflow. Además completa los activos pasados que no fueron cobrados aún. -Mati en proceso de automatización de columnas: año, mes, tipo de activo y cliente -DETROIT se cargó retroactivamente en activo. Lorena no lo tenia presente.
A46: Cashflow
A47: Pasivo
A48: Impuestos
A49: Costos Directos e indirectos
A50: Costos estimados

Sheet Listas
A1: ACTIVO | B1: ACTIVO | C1: ACTIVO / Costos directos e indirectos / Costos Estimados / Protectos confirmados y estimados | D1: Pasivo / Costos directos e indirectos / Costos Estimados | E1: Pasivo / Costos directos e indirectos / Costos Estimados | F1: CASHFLOW | G1: Costos estimados
A2: Concepto/Banco | B2: Tipo de Activo | C2: Cliente | D2: Detalle | E2: Subtipo de costo | F2: Subtipo de ingreso/egreso | G2: Puesto | H2: Mes
A3: Caja | B3: Activo Liquido | C3: Coelsa | D3: Vicky Achabal | E3: Equipo | F3: Equipo | G3: PM | H3: 01 ene
A4: Custodia Socios | B4: Mediano Plazo | C4: Arcos Dorados | D4: Vicky Puricelli | E4: Board | F4: Board | G4: Board | H4: 02 feb
A5: Santander-Galicia-Nación | B5: Clientes a cobrar | C5: Animal Studio | D5: Tomi Criado | E5: Oxean | F5: Oxean | G5: Operation Lead | H5: 03 mar
A6: Santander Inversiones | C6: BID | D6: People | E6: Gastos Varios | F6: Gasto Varios | G6: Analista | H6: 04 abr
A7: Bank Of America | C7: Natura | D7: IIBB | E7: Suscripciones/Herramientas | F7: Suscripciones/Herramientas | G7: Data Tech | H7: 05 may
A8: Transferwise | C8: Betterfly | D8: IVA | E8: Impuestos USA | F8: Impuestos USA | G8: Diseño | H8: 06 jun
A9: Cheques en cartera | C9: Giampaoletti | D9: Tarjeta ARG | E9: Impuestos ARG | F9: Impuestos ARG | G9: Freelance | H9: 07 jul
A10: Deuda Clientes | C10: Google LLC | D10: Impuestos USA | E10: Estudio Contable | F10: Estudio Contable | G10: Marketing | H10: 08 ago
A11: Otras Inversiones | C11: Mastercard | D11: Brandwatch | E11: Otros Proveedores | F11: Otros Proveedores | H11: 09 sep
C12: Moreno Ocampo | D12: Youscan | E12: Administración Finanzas | F12: Administración Finanzas | H12: 10 oct
C13: Sentidos | D13: Otras Suscripciones | E13: Tarjeta | F13: Tarjeta | H13: 11 nov
C14: Play Digital S.A (Modo) | D14: Abogado | E14: People | F14: People | H14: 12 dic
C15: Warner | D15: Regalos | E15: Comisiones Bancarias | F15: Cliente
C16: Netflix | D16: Luan Digital | E16: Equipo - Bono | F16: Movimiento entre cuentas
C17: Vertical Media | D17: Tarjeta USA | E17: Board - Bono
C18: Detroit | D18: Romi Figueroa | E18: Otros Gastos
C19: IRSA | D19: Vanu Lanza | E19: Administración Finanzas - Bono
C20: Uber | D20: Lola Camara | E20: Intereses Oxean
C21: Coca-Cola | D21: Trini Petreigne
C22: Kimberly Clark | D22: Aylu Tamer
C23: Tortugas Open Mall | D23: Maricel Perez
C24: Epical | D24: Mati Gonzalez
C25: Cami Criado | D25: To Merello
C26: PeYa | D26: Cata Astiz
C27: Molino Chacabuco | D27: Ina Ceravolo
C28: PepsiCo | D28: Male Quiroga
D29: Sol Ayala
D30: Xavi Aranzana
D31: Pablo Ovejero
D32: Sandra Heyman
D33: Tomi Facio
D34: Honorarios Oxean
D35: Itecsa
D36: Netquest
D37: Ianece Leandro
D38: Gastón Julian
D39: Belen Lebrón
D40: Estudio Contable
...

Sheet Clasificaciones
A1: Costos indirectos e directos | D1: Clientes activos
A2: Detalle | B2: Subtipo de costo | D2: ARCOS DORADOS ARGENTINA S.A. | E2: Arcos Dorados
A3: Vicky Achabal | B3: Equipo | D3: PLAY DIGITAL S. A. | E3: Play Digital S.A (Modo)
A4: Vicky Puricelli | B4: Board | D4: COMPENSADORA ELECTRONICA SA | E4: Coelsa
A5: Tomi Criado | B5: Board | D5: MORENO OCAMPO | E5: Moreno Ocampo
A6: People | B6: People | D6: WARNER BROS | E6: Warner
A7: IIBB | B7: Impuestos ARG | D7: VERTICAL MEDIA | E7: Vertical Media
A8: IVA | B8: Impuestos ARG | D8: VERTICAL MEDIA LLC | E8: Vertical Media
A9: Tarjeta ARG | B9: Tarjeta | D9: UBER | E9: Uber
A10: Impuestos USA | B10: Impuestos USA | D10: DETROIT | E10: Detroit
A11: Brandwatch | B11: Suscripciones/Herramientas | D11: SERVICIOS INTEGRADOS DE ADMINISTRACION Y ALTA GER | E11: Coca-Cola
A12: Youscan | B12: Suscripciones/Herramientas | D12: KIMBERLY | E12: Kimberly Clark
A13: Otras Suscripciones | B13: Suscripciones/Herramientas | D13: ANIMAL STUDIO S.R.L. | E13: Animal Studio
... A16: Luan Digital | B16: Gastos Varios | D16: Turner International Latin America, Inc. | E16: Warner
A17: Tarjeta USA | B17: Tarjeta
A18: Romi Figueroa | B18: Equipo
A19: Vanu Lanza | B19: Equipo
A20: Lola Camara | B20: Equipo
A21: Trini Petreigne | B21: Equipo
A22: Aylu Tamer | B22: Equipo
A23: Maricel Perez | B23: Equipo
A24: Mati Gonzalez | B24: Equipo
A25: To Merello | B25: Equipo
A26: Cata Astiz | B26: Equipo
A27: Ina Ceravolo | B27: Equipo
A28: Male Quiroga | B28: Equipo
... A53: Cami Burstein | B53: Equipo

Sheet Impuestos
B1: MAYO | D1: JUNIO | F1: JULIO | H1: AGOSTO | J1: SEPTIEMBRE
B2: ARG | C2: USA | D2: ARG | E2: USA | F2: ARG | G2: USA | H2: ARG | I2: USA | J2: ARG | K2: USA
A3: VTAS | B3: 8204981 | C3: 1750 | D3: 8956556 | E3: =1750+7350 -> 9100 | F3: 9826556 | G3: 8450 | H3: =10551741-1441885 -> 9109856 | I3: 133570 | J3: =14705569-1114000 -> 13591569 | K3: 97420
A4: IVA VTAS | B4: =B3*21% -> 1723046 | C4: 0 | D4: =D3*21% -> 1880876.8 | E4: 0 | F4: =F3*21% -> 2063576.8 | G4: 0 | H4: 1913069.8 | J4: =J3*21% -> 2854229.5
A5: COMPRAS (GTOS-COSTOS) | B5: 34213915 | C5: =15553+21000 -> 36553 | D5: 7918673 | E5: 46416 | F5: 4762446 | G5: =4523 -> 4523 | H5: 12853757 | I5: 40061 | J5: 10904521 | K5: 31766
A6: IVA CPRAS | B6: =5490.08+20564.73+23205 -> 49259.81 | D6: =24990+10338.3+5067.77+4560.99 -> 44957.06 | F6: 50775 | H6: 36275 | J6: 42925.05
A7: IVA | B7: =B4-B6 -> 1673786.2 | D7: =D4-D6 -> 1835919.7 | F7: =F4-F6 -> 2012801.8 | H7: =H4-H6 -> 1876794.8 | J7: =J4-J6 -> 2811304.4
A8: IB | B8: =(B3*0.6175*0.03)+(B3*0.3825*0.05) -> 308917.53 | D8: =(D3*0.6175*0.03)+(D3*0.3825*0.05) -> 337214.33 | F8: =(F3*0.6175*0.03)+(F3*0.3825*0.05) -> 369969.83 | H8: =(H3*0.6175*0.03)+(H3*0.3825*0.05) -> 342986.08 | J8: =(J3*0.6175*0.03)+(J3*0.3825*0.05) -> 511722.57
A9: ESTUDIO CONTABLE (con iva) | B9: =(B3*0.006) -> 49229.886 | D9: =D3*0.006 -> 53739.336 | F9: =(F3*0.006)*1.21 -> 71340.797 | H9: =(H3*0.006)*1.21 -> 66137.555 | J9: =(J3*0.006)*1.21 -> 98674.791
A10: GANANCIAS (ANUAL) | C10: =(C3-C5)*12%+C3*3% -> -4123.86 | E10: =(E3-E5)*12%+E3*3% -> -4204.92 | G10: =(G3-G5)*12%+G3*3% -> 724.74 | I10: =(I3-I5)*12%+I3*3% -> 15228.18 | K10: =(K3-K5)*12%+K3*3% -> 10801.08

Sheet Intereses Oxean
B1: Saldo | C1: Interés
A2: 45838 | B2: -91979 | C2: =B2*1% -> -919.79
A3: 45869 | B3: -68302 | C3: =B3*1% -> -683.02
A4: 45900 | B4: -42553 | C4: =B4*1% -> -425.53
A5: 45930 | B5: -74319.94 | C5: =B5*1% -> -743.1994

Sheet Activo
A1: Concepto/Banco | B1: Tipo de Activo | C1: Cliente | D1: Mes | E1: Año | F1: Cobrado/No Cobrado AL CIERRE | G1: Fecha de pago/Nota de credito | H1: Vencido | I1: Fecha Facturación | J1: Nro de Factura/Comprobante | K1: Razón Social/Cliente | L1: Detalle | M1: Fecha de vencimiento | N1: Moneda original ARS | O1: Moneda original USD | P1: Cotización | Q1: Monto Total USD
A2: Santander-Galicia-Nación | B2: =IF( A2="", "", IF( OR(A2="Santander-Galicia-Nación", A2="Bank Of America", A2="Transferwise", A2="Custodia Socios", A2="Cheques en cartera", A2="Caja"), "Activo Liquido", IF( OR(A2="Otras Inversiones", A2="Santander Inversiones"), "Mediano Plazo", IF( A2="Clientes a cobrar", "Clientes a cobrar", "DATO NO CARGADO" ) ) ) ) -> Activo Liquido | C2: =IF(K2="", "", IFERROR(VLOOKUP(K2, Clasificaciones!D:E, 2, FALSE), "DATO NO CARGADO")) | D2: 01 ene | E2: 2025 | H2: =IF( A2="", "", IF( AND( F2="No", OR(G2="",G2>M2), M2<TODAY() ), "Vencido", "A término" ) ) -> A término | N2: 8217613 | P2: =IF(ISBLANK(N2), "", VLOOKUP(D2&" "&E2, 'Info Tipo de Cambio y REM'!$A$24:$B$35, 2, FALSE)) -> 1220 | Q2: =IF(NOT(ISBLANK(N2)), N2 / P2, IF(NOT(ISBLANK(O2)), O2, "")) -> 6735.7484
A3: Bank Of America | B3: =IF( A3="", "", IF( OR(A3="Santander-Galicia-Nación", A3="Bank Of America", A3="Transferwise", A3="Custodia Socios", A3="Cheques en cartera", A3="Caja"), "Activo Liquido", IF( OR(A3="Otras Inversiones", A3="Santander Inversiones"), "Mediano Plazo", IF( A3="Clientes a cobrar", "Clientes a cobrar", "DATO NO CARGADO" ) ) ) ) -> Activo Liquido | C3: =IF(K3="", "", IFERROR(VLOOKUP(K3, Clasificaciones!D:E, 2, FALSE), "DATO NO CARGADO")) | D3: 01 ene | E3: 2025 | H3: =IF( A3="", "", IF( AND( F3="No", OR(G3="",G3>M3), M3<TODAY() ), "Vencido", "A término" ) ) -> A término | O3: -2840 | P3: =IF(ISBLANK(N3), "", VLOOKUP(D3&" "&E3, 'Info Tipo de Cambio y REM'!$A$24:$B$35, 2, FALSE)) | Q3: =IF(NOT(ISBLANK(N3)), N3 / P3, IF(NOT(ISBLANK(O3)), O3, "")) -> -2840
A4: Transferwise | B4: =IF( A4="", "", IF( OR(A4="Santander-Galicia-Nación", A4="Bank Of America", A4="Transferwise", A4="Custodia Socios", A4="Cheques en cartera", A4="Caja"), "Activo Liquido", IF( OR(A4="Otras Inversiones", A4="Santander Inversiones"), "Mediano Plazo", IF( A4="Clientes a cobrar", "Clientes a cobrar", "DATO NO CARGADO" ) ) ) ) -> Activo Liquido | C4: =IF(K4="", "", IFERROR(VLOOKUP(K4, Clasificaciones!D:E, 2, FALSE), "DATO NO CARGADO")) | D4: 01 ene | E4: 2025 | H4: =IF( A4="", "", IF( AND( F4="No", OR(G4="",G4>M4), M4<TODAY() ), "Vencido", "A término" ) ) -> A término | O4: 230 | P4: =IF(ISBLANK(N4), "", VLOOKUP(D4&" "&E4, 'Info Tipo de Cambio y REM'!$A$24:$B$35, 2, FALSE)) | Q4: =IF(NOT(ISBLANK(N4)), N4 / P4, IF(NOT(ISBLANK(O4)), O4, "")) -> 230
A5: Otras Inversiones | B5: =IF( A5="", "", IF( OR(A5="Santander-Galicia-Nación", A5="Bank Of America", A5="Transferwise", A5="Custodia Socios", A5="Cheques en cartera", A5="Caja"), "Activo Liquido", IF( OR(A5="Otras Inversiones", A5="Santander Inversiones"), "Mediano Plazo", IF( A5="Clientes a cobrar", "Clientes a cobrar", "DATO NO CARGADO" ) ) ) ) -> Mediano Plazo | C5: =IF(K5="", "", IFERROR(VLOOKUP(K5, Clasificaciones!D:E, 2, FALSE), "DATO NO CARGADO")) | D5: 01 ene | E5: 2025 | H5: =IF( A5="", "", IF( AND( F5="No", OR(G5="",G5>M5), M5<TODAY() ), "Vencido", "A término" ) ) -> A término | O5: 9200 | P5: =IF(ISBLANK(N5), "", VLOOKUP(D5&" "&E5, 'Info Tipo de Cambio y REM'!$A$24:$B$35, 2, FALSE)) | Q5: =IF(NOT(ISBLANK(N5)), N5 / P5, IF(NOT(ISBLANK(O5)), O5, "")) -> 9200
A6: Clientes a cobrar | B6: =IF( A6="", "", IF( OR(A6="Santander-Galicia-Nación", A6="Bank Of America", A6="Transferwise", A6="Custodia Socios", A6="Cheques en cartera", A6="Caja"), "Activo Liquido", IF( OR(A6="Otras Inversiones", A6="Santander Inversiones"), "Mediano Plazo", IF( A6="Clientes a cobrar", "Clientes a cobrar", "DATO NO CARGADO" ) ) ) ) -> Clientes a cobrar | C6: =IF(K6="", "", IFERROR(VLOOKUP(K6, Clasificaciones!D:E, 2, FALSE), "DATO NO CARGADO")) -> Arcos Dorados | D6: 01 ene | E6: 2025 | H6: =IF( A6="", "", IF( AND( F6="No", OR(G6="",G6>M6), M6<TODAY() ), "Vencido", "A término" ) ) -> A término | J6: Factura de Crédito MiPyME (FCE) N° A-00008-00000898 | K6: ARCOS DORADOS ARGENTINA S.A. | M6: 45680 | N6: 508200 | P6: =IF(ISBLANK(N6), "", VLOOKUP(D6&" "&E6, 'Info Tipo de Cambio y REM'!$A$24:$B$35, 2, FALSE)) -> 1220 | Q6: =IF(NOT(ISBLANK(N6)), N6 / P6, IF(NOT(ISBLANK(O6)), O6, "")) -> 416.55738
A7: Clientes a cobrar | B7: =IF( A7="", "", IF( OR(A7="Santander-Galicia-Nación", A7="Bank Of America", A7="Transferwise", A7="Custodia Socios", A7="Cheques en cartera", A7="Caja"), "Activo Liquido", IF( OR(A7="Otras Inversiones", A7="Santander Inversiones"), "Mediano Plazo", IF( A7="Clientes a cobrar", "Clientes a cobrar", "DATO NO CARGADO" ) ) ) ) -> Clientes a cobrar | C7: =IF(K7="", "", IFERROR(VLOOKUP(K7, Clasificaciones!D:E, 2, FALSE), "DATO NO CARGADO")) -> Play Digital S.A (Modo) | D7: 01 ene | E7: 2025 | H7: =IF( A7="", "", IF( AND( F7="No", OR(G7="",G7>M7), M7<TODAY() ), "Vencido", "A término" ) ) -> A término | J7: Factura de Venta N° A-00008-00001931 | K7: PLAY DIGITAL S. A. | M7: 45688 | N7: 4744208 | P7: =IF(ISBLANK(N7), "", VLOOKUP(D7&" "&E7, 'Info Tipo de Cambio y REM'!$A$24:$B$35, 2, FALSE)) -> 1220 | Q7: =IF(NOT(ISBLANK(N7)), N7 / P7, IF(NOT(ISBLANK(O7)), O7, "")) -> 3888.6951
A8: Clientes a cobrar | B8: =IF( A8="", "", IF( OR(A8="Santander-Galicia-Nación", A8="Bank Of America", A8="Transferwise", A8="Custodia Socios", A8="Cheques en cartera", A8="Caja"), "Activo Liquido", IF( OR(A8="Otras Inversiones", A8="Santander Inversiones"), "Mediano Plazo", IF( A8="Clientes a cobrar", "Clientes a cobrar", "DATO NO CARGADO" ) ) ) ) -> Clientes a cobrar | C8: =IF(K8="", "", IFERROR(VLOOKUP(K8, Clasificaciones!D:E, 2, FALSE), "DATO NO CARGADO")) -> Coelsa | D8: 01 ene | E8: 2025 | H8: =IF( A8="", "", IF( AND( F8="No", OR(G8="",G8>M8), M8<TODAY() ), "Vencido", "A término" ) ) -> A término | J8: Factura de Crédito MiPyME (FCE) N° A-00008-00000886 | K8: COMPENSADORA ELECTRONICA SA | M8: 45659 | N8: 4499766 | P8: =IF(ISBLANK(N8), "", VLOOKUP(D8&" "&E8, 'Info Tipo de Cambio y REM'!$A$24:$B$35, 2, FALSE)) -> 1220 | Q8: =IF(NOT(ISBLANK(N8)), N8 / P8, IF(NOT(ISBLANK(O8)), O8, "")) -> 3688.3328
A9: Clientes a cobrar | B9: =IF( A9="", "", IF( OR(A9="Santander-Galicia-Nación", A9="Bank Of America", A9="Transferwise", A9="Custodia Socios", A9="Cheques en cartera", A9="Caja"), "Activo Liquido", IF( OR(A9="Otras Inversiones", A9="Santander Inversiones"), "Mediano Plazo", IF( A9="Clientes a cobrar", "Clientes a cobrar", "DATO NO CARGADO" ) ) ) ) -> Clientes a cobrar | C9: =IF(K9="", "", IFERROR(VLOOKUP(K9, Clasificaciones!D:E, 2, FALSE), "DATO NO CARGADO")) -> Moreno Ocampo | D9: 01 ene | E9: 2025 | H9: =IF( A9="", "", IF( AND( F9="No", OR(G9="",G9>M9), M9<TODAY() ), "Vencido", "A término" ) ) -> A término | J9: Invoice 532 | K9: MORENO OCAMPO | M9: 45678 | O9: 250 | P9: =IF(ISBLANK(N9), "", VLOOKUP(D9&" "&E9, 'Info Tipo de Cambio y REM'!$A$24:$B$35, 2, FALSE)) | Q9: =IF(NOT(ISBLANK(N9)), N9 / P9, IF(NOT(ISBLANK(O9)), O9, "")) -> 250
A10: Clientes a cobrar | B10: =IF( A10="", "", IF( OR(A10="Santander-Galicia-Nación", A10="Bank Of America", A10="Transferwise", A10="Custodia Socios", A10="Cheques en cartera", A10="Caja"), "Activo Liquido", IF( OR(A10="Otras Inversiones", A10="Santander Inversiones"), "Mediano Plazo", IF( A10="Clientes a cobrar", "Clientes a cobrar", "DATO NO CARGADO" ) ) ) ) -> Clientes a cobrar | C10: =IF(K10="", "", IFERROR(VLOOKUP(K10, Clasificaciones!D:E, 2, FALSE), "DATO NO CARGADO")) -> Warner | D10: 01 ene | E10: 2025 | H10: =IF( A10="", "", IF( AND( F10="No", OR(G10="",G10>M10), M10<TODAY() ), "Vencido", "A término" ) ) -> A término | J10: Invoice 515 | K10: WARNER BROS | M10: 45714 | O10: 13450 | P10: =IF(ISBLANK(N10), "", VLOOKUP(D10&" "&E10, 'Info Tipo de Cambio y REM'!$A$24:$B$35, 2, FALSE)) | Q10: =IF(NOT(ISBLANK(N10)), N10 / P10, IF(NOT(ISBLANK(O10)), O10, "")) -> 13450
A11: Clientes a cobrar | B11: =IF( A11="", "", IF( OR(A11="Santander-Galicia-Nación", A11="Bank Of America", A11="Transferwise", A11="Custodia Socios", A11="Cheques en cartera", A11="Caja"), "Activo Liquido", IF( OR(A11="Otras Inversiones", A11="Santander Inversiones"), "Mediano Plazo", IF( A11="Clientes a cobrar", "Clientes a cobrar", "DATO NO CARGADO" ) ) ) ) -> Clientes a cobrar | C11: =IF(K11="", "", IFERROR(VLOOKUP(K11, Clasificaciones!D:E, 2, FALSE), "DATO NO CARGADO")) -> Warner | D11: 01 ene | E11: 2025 | H11: =IF( A11="", "", IF( AND( F11="No", OR(G11="",G11>M11), M11<TODAY() ), "Vencido", "A término" ) ) -> A término | J11: Invoice 525 | K11: WARNER BROS | M11: 45726 | O11: 13450 | P11: =IF(ISBLANK(N11), "", VLOOKUP(D11&" "&E11, 'Info Tipo de Cambio y REM'!$A$24:$B$35, 2, FALSE)) | Q11: =IF(NOT(ISBLANK(N11)), N11 / P11, IF(NOT(ISBLANK(O11)), O11, "")) -> 13450
A12: Clientes a cobrar | B12: =IF( A12="", "", IF( OR(A12="Santander-Galicia-Nación", A12="Bank Of America", A12="Transferwise", A12="Custodia Socios", A12="Cheques en cartera", A12="Caja"), "Activo Liquido", IF( OR(A12="Otras Inversiones", A12="Santander Inversiones"), "Mediano Plazo", IF( A12="Clientes a cobrar", "Clientes a cobrar", "DATO NO CARGADO" ) ) ) ) -> Clientes a cobrar | C12: =IF(K12="", "", IFERROR(VLOOKUP(K12, Clasificaciones!D:E, 2, FALSE), "DATO NO CARGADO")) -> Warner | D12: 01 ene | E12: 2025 | H12: =IF( A12="", "", IF( AND( F12="No", OR(G12="",G12>M12), M12<TODAY() ), "Vencido", "A término" ) ) -> A término | J12: Invoice 534 | K12: WARNER BROS | M12: 45750 | O12: 13450 | P12: =IF(ISBLANK(N12), "", VLOOKUP(D12&" "&E12, 'Info Tipo de Cambio y REM'!$A$24:$B$35, 2, FALSE)) | Q12: =IF(NOT(ISBLANK(N12)), N12 / P12, IF(NOT(ISBLANK(O12)), O12, "")) -> 13450
A13: Clientes a cobrar | B13: =IF( A13="", "", IF( OR(A13="Santander-Galicia-Nación", A13="Bank Of America", A13="Transferwise", A13="Custodia Socios", A13="Cheques en cartera", A13="Caja"), "Activo Liquido", IF( OR(A13="Otras Inversiones", A13="Santander Inversiones"), "Mediano Plazo", IF( A13="Clientes a cobrar", "Clientes a cobrar", "DATO NO CARGADO" ) ) ) ) -> Clientes a cobrar | C13: =IF(K13="", "", IFERROR(VLOOKUP(K13, Clasificaciones!D:E, 2, FALSE), "DATO NO CARGADO")) -> Vertical Media | D13: 01 ene | E13: 2025 | H13: =IF( A13="", "", IF( AND( F13="No", OR(G13="",G13>M13), M13<TODAY() ), "Vencido", "A término" ) ) -> A término | J13: INVOICE 539 | K13: VERTICAL MEDIA | M13: 45704 | O13: 1750 | P13: =IF(ISBLANK(N13), "", VLOOKUP(D13&" "&E13, 'Info Tipo de Cambio y REM'!$A$24:$B$35, 2, FALSE)) | Q13: =IF(NOT(ISBLANK(N13)), N13 / P13, IF(NOT(ISBLANK(O13)), O13, "")) -> 1750
A14: Clientes a cobrar | B14: =IF( A14="", "", IF( OR(A14="Santander-Galicia-Nación", A14="Bank Of America", A14="Transferwise", A14="Custodia Socios", A14="Cheques en cartera", A14="Caja"), "Activo Liquido", IF( OR(A14="Otras Inversiones", A14="Santander Inversiones"), "Mediano Plazo", IF( A14="Clientes a cobrar", "Clientes a cobrar", "DATO NO CARGADO" ) ) ) ) -> Clientes a cobrar | C14: =IF(K14="", "", IFERROR(VLOOKUP(K14, Clasificaciones!D:E, 2, FALSE), "DATO NO CARGADO")) -> Uber | D14: 01 ene | E14: 2025 | H14: =IF( A14="", "", IF( AND( F14="No", OR(G14="",G14>M14), M14<TODAY() ), "Vencido", "A término" ) ) -> A término | J14: Invoice 520 | K14: UBER | M14: 45690 | O14: 7150 | P14: =IF(ISBLANK(N14), "", VLOOKUP(D14&" "&E14, 'Info Tipo de Cambio y REM'!$A$24:$B$35, 2, FALSE)) | Q14: =IF(NOT(ISBLANK(N14)), N14 / P14, IF(NOT(ISBLANK(O14)), O14, "")) -> 7150
A15: Santander-Galicia-Nación | B15: =IF( A15="", "", IF( OR(A15="Santander-Galicia-Nación", A15="Bank Of America", A15="Transferwise", A15="Custodia Socios", A15="Cheques en cartera", A15="Caja"), "Activo Liquido", IF( OR(A15="Otras Inversiones", A15="Santander Inversiones"), "Mediano Plazo", IF( A15="Clientes a cobrar", "Clientes a cobrar", "DATO NO CARGADO" ) ) ) ) -> Activo Liquido | C15: =IF(K15="", "", IFERROR(VLOOKUP(K15, Clasificaciones!D:E, 2, FALSE), "DATO NO CARGADO")) | D15: 02 feb | E15: 2025 | H15: =IF( A15="", "", IF( AND( F15="No", OR(G15="",G15>M15), M15<TODAY() ), "Vencido", "A término" ) ) -> A término | N15: 29367 | P15: =IF(ISBLANK(N15), "", VLOOKUP(D15&" "&E15, 'Info Tipo de Cambio y REM'!$A$24:$B$35, 2, FALSE)) -> 1230 | Q15: =IF(NOT(ISBLANK(N15)), N15 / P15, IF(NOT(ISBLANK(O15)), O15, "")) -> 23.87561
A16: Bank Of America | B16: =IF( A16="", "", IF( OR(A16="Santander-Galicia-Nación", A16="Bank Of America", A16="Transferwise", A16="Custodia Socios", A16="Cheques en cartera", A16="Caja"), "Activo Liquido", IF( OR(A16="Otras Inversiones", A16="Santander Inversiones"), "Mediano Plazo", IF( A16="Clientes a cobrar", "Clientes a cobrar", "DATO NO CARGADO" ) ) ) ) -> Activo Liquido | C16: =IF(K16="", "", IFERROR(VLOOKUP(K16, Clasificaciones!D:E, 2, FALSE), "DATO NO CARGADO")) | D16: 02 feb | E16: 2025 | H16: =IF( A16="", "", IF( AND( F16="No", OR(G16="",G16>M16), M16<TODAY() ), "Vencido", "A término" ) ) -> A término | O16: -7604 | P16: =IF(ISBLANK(N16), "", VLOOKUP(D16&" "&E16, 'Info Tipo de Cambio y REM'!$A$24:$B$35, 2, FALSE)) | Q16: =IF(NOT(ISBLANK(N16)), N16 / P16, IF(NOT(ISBLANK(O16)), O16, "")) -> -7604
A17: Transferwise | B17: =IF( A17="", "", IF( OR(A17="Santander-Galicia-Nación", A17="Bank Of America", A17="Transferwise", A17="Custodia Socios", A17="Cheques en cartera", A17="Caja"), "Activo Liquido", IF( OR(A17="Otras Inversiones", A17="Santander Inversiones"), "Mediano Plazo", IF( A17="Clientes a cobrar", "Clientes a cobrar", "DATO NO CARGADO" ) ) ) ) -> Activo Liquido | C17: =IF(K17="", "", IFERROR(VLOOKUP(K17, Clasificaciones!D:E, 2, FALSE), "DATO NO CARGADO")) | D17: 02 feb | E17: 2025 | H17: =IF( A17="", "", IF( AND( F17="No", OR(G17="",G17>M17), M17<TODAY() ), "Vencido", "A término" ) ) -> A término | O17: 230 | P17: =IF(ISBLANK(N17), "", VLOOKUP(D17&" "&E17, 'Info Tipo de Cambio y REM'!$A$24:$B$35, 2, FALSE)) | Q17: =IF(NOT(ISBLANK(N17)), N17 / P17, IF(NOT(ISBLANK(O17)), O17, "")) -> 230
A18: Otras Inversiones | B18: =IF( A18="", "", IF( OR(A18="Santander-Galicia-Nación", A18="Bank Of America", A18="Transferwise", A18="Custodia Socios", A18="Cheques en cartera", A18="Caja"), "Activo Liquido", IF( OR(A18="Otras Inversiones", A18="Santander Inversiones"), "Mediano Plazo", IF( A18="Clientes a cobrar", "Clientes a cobrar", "DATO NO CARGADO" ) ) ) ) -> Mediano Plazo | C18: =IF(K18="", "", IFERROR(VLOOKUP(K18, Clasificaciones!D:E, 2, FALSE), "DATO NO CARGADO")) | D18: 02 feb | E18: 2025 | H18: =IF( A18="", "", IF( AND( F18="No", OR(G18="",G18>M18), M18<TODAY() ), "Vencido", "A término" ) ) -> A término | O18: 6983 | P18: =IF(ISBLANK(N18), "", VLOOKUP(D18&" "&E18, 'Info Tipo de Cambio y REM'!$A$24:$B$35, 2, FALSE)) | Q18: =IF(NOT(ISBLANK(N18)), N18 / P18, IF(NOT(ISBLANK(O18)), O18, "")) -> 6983
A19: Clientes a cobrar | B19: =IF( A19="", "", IF( OR(A19="Santander-Galicia-Nación", A19="Bank Of America", A19="Transferwise", A19="Custodia Socios", A19="Cheques en cartera", A19="Caja"), "Activo Liquido", IF( OR(A19="Otras Inversiones", A19="Santander Inversiones"), "Mediano Plazo", IF( A19="Clientes a cobrar", "Clientes a cobrar", "DATO NO CARGADO" ) ) ) ) -> Clientes a cobrar | C19: =IF(K19="", "", IFERROR(VLOOKUP(K19, Clasificaciones!D:E, 2, FALSE), "DATO NO CARGADO")) -> Play Digital S.A (Modo) | D19: 02 feb | E19: 2025 | H19: =IF( A19="", "", IF( AND( F19="No", OR(G19="",G19>M19), M19<TODAY() ), "Vencido", "A término" ) ) -> A término | J19: Factura de Venta N° A-00008-00001937 | K19: PLAY DIGITAL S. A. | M19: 45719 | N19: 4744208 | P19: =IF(ISBLANK(N19), "", VLOOKUP(D19&" "&E19, 'Info Tipo de Cambio y REM'!$A$24:$B$35, 2, FALSE)) -> 1230 | Q19: =IF(NOT(ISBLANK(N19)), N19 / P19, IF(NOT(ISBLANK(O19)), O19, "")) -> 3857.0797
A20: Clientes a cobrar | B20: =IF( A20="", "", IF( OR(A20="Santander-Galicia-Nación", A20="Bank Of America", A20="Transferwise", A20="Custodia Socios", A20="Cheques en cartera", A20="Caja"), "Activo Liquido", IF( OR(A20="Otras Inversiones", A20="Santander Inversiones"), "Mediano Plazo", IF( A20="Clientes a cobrar", "Clientes a cobrar", "DATO NO CARGADO" ) ) ) ) -> Clientes a cobrar | C20: =IF(K20="", "", IFERROR(VLOOKUP(K20, Clasificaciones!D:E, 2, FALSE), "DATO NO CARGADO")) -> Coelsa | D20: 02 feb | E20: 2025 | H20: =IF( A20="", "", IF( AND( F20="No", OR(G20="",G20>M20), M20<TODAY() ), "Vencido", "A término" ) ) -> A término | J20: Factura de Crédito MiPyME (FCE) N° A-00008-00000906 | K20: COMPENSADORA ELECTRONICA SA | M20: 45719 | N20: 4499766 | P20: =IF(ISBLANK(N20), "", VLOOKUP(D20&" "&E20, 'Info Tipo de Cambio y REM'!$A$24:$B$35, 2, FALSE)) -> 1230 | Q20: =IF(NOT(ISBLANK(N20)), N20 / P20, IF(NOT(ISBLANK(O20)), O20, "")) -> 3658.3463
A21: Clientes a cobrar | B21: =IF( A21="", "", IF( OR(A21="Santander-Galicia-Nación", A21="Bank Of America", A21="Transferwise", A21="Custodia Socios", A21="Cheques en cartera", A21="Caja"), "Activo Liquido", IF( OR(A21="Otras Inversiones", A21="Santander Inversiones"), "Mediano Plazo", IF( A21="Clientes a cobrar", "Clientes a cobrar", "DATO NO CARGADO" ) ) ) ) -> Clientes a cobrar | C21: =IF(K21="", "", IFERROR(VLOOKUP(K21, Clasificaciones!D:E, 2, FALSE), "DATO NO CARGADO")) -> Moreno Ocampo | D21: 02 feb | E21: 2025 | H21: =IF( A21="", "", IF( AND( F21="No", OR(G21="",G21>M21), M21<TODAY() ), "Vencido", "A término" ) ) -> A término | J21: Invoice 532 | K21: MORENO OCAMPO | M21: 45678 | O21: 250 | P21: =IF(ISBLANK(N21), "", VLOOKUP(D21&" "&E21, 'Info Tipo de Cambio y REM'!$A$24:$B$35, 2, FALSE)) | Q21: =IF(NOT(ISBLANK(N21)), N21 / P21, IF(NOT(ISBLANK(O21)), O21, "")) -> 250
A22: Clientes a cobrar | B22: =IF( A22="", "", IF( OR(A22="Santander-Galicia-Nación", A22="Bank Of America", A22="Transferwise", A22="Custodia Socios", A22="Cheques en cartera", A22="Caja"), "Activo Liquido", IF( OR(A22="Otras Inversiones", A22="Santander Inversiones"), "Mediano Plazo", IF( A22="Clientes a cobrar", "Clientes a cobrar", "DATO NO CARGADO" ) ) ) ) -> Clientes a cobrar | C22: =IF(K22="", "", IFERROR(VLOOKUP(K22, Clasificaciones!D:E, 2, FALSE), "DATO NO CARGADO")) -> Warner | D22: 02 feb | E22: 2025 | H22: =IF( A22="", "", IF( AND( F22="No", OR(G22="",G22>M22), M22<TODAY() ), "Vencido", "A término" ) ) -> A término | J22: Invoice 525 | K22: WARNER BROS | M22: 45726 | O22: 13450 | P22: =IF(ISBLANK(N22), "", VLOOKUP(D22&" "&E22, 'Info Tipo de Cambio y REM'!$A$24:$B$35, 2, FALSE)) | Q22: =IF(NOT(ISBLANK(N22)), N22 / P22, IF(NOT(ISBLANK(O22)), O22, "")) -> 13450
A23: Clientes a cobrar | B23: =IF( A23="", "", IF( OR(A23="Santander-Galicia-Nación", A23="Bank Of America", A23="Transferwise", A23="Custodia Socios", A23="Cheques en cartera", A23="Caja"), "Activo Liquido", IF( OR(A23="Otras Inversiones", A23="Santander Inversiones"), "Mediano Plazo", IF( A23="Clientes a cobrar", "Clientes a cobrar", "DATO NO CARGADO" ) ) ) ) -> Clientes a cobrar | C23: =IF(K23="", "", IFERROR(VLOOKUP(K23, Clasificaciones!D:E, 2, FALSE), "DATO NO CARGADO")) -> Warner | D23: 02 feb | E23: 2025 | H23: =IF( A23="", "", IF( AND( F23="No", OR(G23="",G23>M23), M23<TODAY() ), "Vencido", "A término" ) ) -> A término | J23: Invoice 534 | K23: WARNER BROS | M23: 45750 | O23: 13450 | P23: =IF(ISBLANK(N23), "", VLOOKUP(D23&" "&E23, 'Info Tipo de Cambio y REM'!$A$24:$B$35, 2, FALSE)) | Q23: =IF(NOT(ISBLANK(N23)), N23 / P23, IF(NOT(ISBLANK(O23)), O23, "")) -> 13450
A24: Clientes a cobrar | B24: =IF( A24="", "", IF( OR(A24="Santander-Galicia-Nación", A24="Bank Of America", A24="Transferwise", A24="Custodia Socios", A24="Cheques en cartera", A24="Caja"), "Activo Liquido", IF( OR(A24="Otras Inversiones", A24="Santander Inversiones"), "Mediano Plazo", IF( A24="Clientes a cobrar", "Clientes a cobrar", "DATO NO CARGADO" ) ) ) ) -> Clientes a cobrar | C24: =IF(K24="", "", IFERROR(VLOOKUP(K24, Clasificaciones!D:E, 2, FALSE), "DATO NO CARGADO")) -> Warner | D24: 02 feb | E24: 2025 | H24: =IF( A24="", "", IF( AND( F24="No", OR(G24="",G24>M24), M24<TODAY() ), "Vencido", "A término" ) ) -> A término | J24: Invoice 547 | K24: WARNER BROS | M24: 45782 | O24: 13450 | P24: =IF(ISBLANK(N24), "", VLOOKUP(D24&" "&E24, 'Info Tipo de Cambio y REM'!$A$24:$B$35, 2, FALSE)) | Q24: =IF(NOT(ISBLANK(N24)), N24 / P24, IF(NOT(ISBLANK(O24)), O24, "")) -> 13450
A25: Clientes a cobrar | B25: =IF( A25="", "", IF( OR(A25="Santander-Galicia-Nación", A25="Bank Of America", A25="Transferwise", A25="Custodia Socios", A25="Cheques en cartera", A25="Caja"), "Activo Liquido", IF( OR(A25="Otras Inversiones", A25="Santander Inversiones"), "Mediano Plazo", IF( A25="Clientes a cobrar", "Clientes a cobrar", "DATO NO CARGADO" ) ) ) ) -> Clientes a cobrar | C25: =IF(K25="", "", IFERROR(VLOOKUP(K25, Clasificaciones!D:E, 2, FALSE), "DATO NO CARGADO")) -> Vertical Media | D25: 02 feb | E25: 2025 | H25: =IF( A25="", "", IF( AND( F25="No", OR(G25="",G25>M25), M25<TODAY() ), "Vencido", "A término" ) ) -> A término | J25: Invoice 544 | K25: VERTICAL MEDIA | M25: 45719 | O25: 1750 | P25: =IF(ISBLANK(N25), "", VLOOKUP(D25&" "&E25, 'Info Tipo de Cambio y REM'!$A$24:$B$35, 2, FALSE)) | Q25: =IF(NOT(ISBLANK(N25)), N25 / P25, IF(NOT(ISBLANK(O25)), O25, "")) -> 1750
A26: Santander-Galicia-Nación | B26: =IF( A26="", "", IF( OR(A26="Santander-Galicia-Nación", A26="Bank Of America", A26="Transferwise", A26="Custodia Socios", A26="Cheques en cartera", A26="Caja"), "Activo Liquido", IF( OR(A26="Otras Inversiones", A26="Santander Inversiones"), "Mediano Plazo", IF( A26="Clientes a cobrar", "Clientes a cobrar", "DATO NO CARGADO" ) ) ) ) -> Activo Liquido | C26: =IF(K26="", "", IFERROR(VLOOKUP(K26, Clasificaciones!D:E, 2, FALSE), "DATO NO CARGADO")) | D26: 03 mar | E26: 2025 | H26: =IF( A26="", "", IF( AND( F26="No", OR(G26="",G26>M26), M26<TODAY() ), "Vencido", "A término" ) ) -> A término | N26: -429974 | P26: =IF(ISBLANK(N26), "", VLOOKUP(D26&" "&E26, 'Info Tipo de Cambio y REM'!$A$24:$B$35, 2, FALSE)) -> 1325 | Q26: =IF(NOT(ISBLANK(N26)), N26 / P26, IF(NOT(ISBLANK(O26)), O26, "")) -> -324.50868
A27: Bank Of America | B27: =IF( A27="", "", IF( OR(A27="Santander-Galicia-Nación", A27="Bank Of America", A27="Transferwise", A27="Custodia Socios", A27="Cheques en cartera", A27="Caja"), "Activo Liquido", IF( OR(A27="Otras Inversiones", A27="Santander Inversiones"), "Mediano Plazo", IF( A27="Clientes a cobrar", "Clientes a cobrar", "DATO NO CARGADO" ) ) ) ) -> Activo Liquido | C27: =IF(K27="", "", IFERROR(VLOOKUP(K27, Clasificaciones!D:E, 2, FALSE), "DATO NO CARGADO")) | D27: 03 mar | E27: 2025 | H27: =IF( A27="", "", IF( AND( F27="No", OR(G27="",G27>M27), M27<TODAY() ), "Vencido", "A término" ) ) -> A término | O27: -26706 | P27: =IF(ISBLANK(N27), "", VLOOKUP(D27&" "&E27, 'Info Tipo de Cambio y REM'!$A$24:$B$35, 2, FALSE)) | Q27: =IF(NOT(ISBLANK(N27)), N27 / P27, IF(NOT(ISBLANK(O27)), O27, "")) -> -26706
A28: Transferwise | B28: =IF( A28="", "", IF( OR(A28="Santander-Galicia-Nación", A28="Bank Of America", A28="Transferwise", A28="Custodia Socios", A28="Cheques en cartera", A28="Caja"), "Activo Liquido", IF( OR(A28="Otras Inversiones", A28="Santander Inversiones"), "Mediano Plazo", IF( A28="Clientes a cobrar", "Clientes a cobrar", "DATO NO CARGADO" ) ) ) ) -> Activo Liquido | C28: =IF(K28="", "", IFERROR(VLOOKUP(K28, Clasificaciones!D:E, 2, FALSE), "DATO NO CARGADO")) | D28: 03 mar | E28: 2025 | H28: =IF( A28="", "", IF( AND( F28="No", OR(G28="",G28>M28), M28<TODAY() ), "Vencido", "A término" ) ) -> A término | O28: 230 | P28: =IF(ISBLANK(N28), "", VLOOKUP(D28&" "&E28, 'Info Tipo de Cambio y REM'!$A$24:$B$35, 2, FALSE)) | Q28: =IF(NOT(ISBLANK(N28)), N28 / P28, IF(NOT(ISBLANK(O28)), O28, "")) -> 230
A29: Otras Inversiones | B29: =IF( A29="", "", IF( OR(A29="Santander-Galicia-Nación", A29="Bank Of America", A29="Transferwise", A29="Custodia Socios", A29="Cheques en cartera", A29="Caja"), "Activo Liquido", IF( OR(A29="Otras Inversiones", A29="Santander Inversiones"), "Mediano Plazo", IF( A29="Clientes a cobrar", "Clientes a cobrar", "DATO NO CARGADO" ) ) ) ) -> Mediano Plazo | C29: =IF(K29="", "", IFERROR(VLOOKUP(K29, Clasificaciones!D:E, 2, FALSE), "DATO NO CARGADO")) | D29: 03 mar | E29: 2025 | H29: =IF( A29="", "", IF( AND( F29="No", OR(G29="",G29>M29), M29<TODAY() ), "Vencido", "A término" ) ) -> A término | O29: 2499 | P29: =IF(ISBLANK(N29), "", VLOOKUP(D29&" "&E29, 'Info Tipo de Cambio y REM'!$A$24:$B$35, 2, FALSE)) | Q29: =IF(NOT(ISBLANK(N29)), N29 / P29, IF(NOT(ISBLANK(O29)), O29, "")) -> 2499
A30: Clientes a cobrar | B30: =IF( A30="", "", IF( OR(A30="Santander-Galicia-Nación", A30="Bank Of America", A30="Transferwise", A30="Custodia Socios", A30="Cheques en cartera", A30="Caja"), "Activo Liquido", IF( OR(A30="Otras Inversiones", A30="Santander Inversiones"), "Mediano Plazo", IF( A30="Clientes a cobrar", "Clientes a cobrar", "DATO NO CARGADO" ) ) ) ) -> Clientes a cobrar | C30: =IF(K30="", "", IFERROR(VLOOKUP(K30, Clasificaciones!D:E, 2, FALSE), "DATO NO CARGADO")) -> Play Digital S.A (Modo) | D30: 03 mar | E30: 2025 | H30: =IF( A30="", "", IF( AND( F30="No", OR(G30="",G30>M30), M30<TODAY() ), "Vencido", "A término" ) ) -> A término | J30: Factura de Venta N° A-00008-00001939 | K30: PLAY DIGITAL S. A. | M30: 45752 | N30: 5095280 | P30: =IF(ISBLANK(N30), "", VLOOKUP(D30&" "&E30, 'Info Tipo de Cambio y REM'!$A$24:$B$35, 2, FALSE)) -> 1325 | Q30: =IF(NOT(ISBLANK(N30)), N30 / P30, IF(NOT(ISBLANK(O30)), O30, "")) -> 3845.4943
A31: Clientes a cobrar | B31: =IF( A31="", "", IF( OR(A31="Santander-Galicia-Nación", A31="Bank Of America", A31="Transferwise", A31="Custodia Socios", A31="Cheques en cartera", A31="Caja"), "Activo Liquido", IF( OR(A31="Otras Inversiones", A31="Santander Inversiones"), "Mediano Plazo", IF( A31="Clientes a cobrar", "Clientes a cobrar", "DATO NO CARGADO" ) ) ) ) -> Clientes a cobrar | C31: =IF(K31="", "", IFERROR(VLOOKUP(K31, Clasificaciones!D:E, 2, FALSE), "DATO NO CARGADO")) -> Coelsa | D31: 03 mar | E31: 2025 | H31: =IF( A31="", "", IF( AND( F31="No", OR(G31="",G31>M31), M31<TODAY() ), "Vencido", "A término" ) ) -> A término | J31: Factura de Crédito MiPyME (FCE) N° A-00008-00000922 | K31: COMPENSADORA ELECTRONICA SA | M31: 45752 | N31: 4832747 | P31: =IF(ISBLANK(N31), "", VLOOKUP(D31&" "&E31, 'Info Tipo de Cambio y REM'!$A$24:$B$35, 2, FALSE)) -> 1325 | Q31: =IF(NOT(ISBLANK(N31)), N31 / P31, IF(NOT(ISBLANK(O31)), O31, "")) -> 3647.3562
A32: Clientes a cobrar | B32: =IF( A32="", "", IF( OR(A32="Santander-Galicia-Nación", A32="Bank Of America", A32="Transferwise", A32="Custodia Socios", A32="Cheques en cartera", A32="Caja"), "Activo Liquido", IF( OR(A32="Otras Inversiones", A32="Santander Inversiones"), "Mediano Plazo", IF( A32="Clientes a cobrar", "Clientes a cobrar", "DATO NO CARGADO" ) ) ) ) -> Clientes a cobrar | C32: =IF(K32="", "", IFERROR(VLOOKUP(K32, Clasificaciones!D:E, 2, FALSE), "DATO NO CARGADO")) -> Arcos Dorados | D32: 03 mar | E32: 2025 | H32: =IF( A32="", "", IF( AND( F32="No", OR(G32="",G32>M32), M32<TODAY() ), "Vencido", "A término" ) ) -> A término | J32: Factura de Crédito MiPyME (FCE) N° A-00008-00000925 | K32: ARCOS DORADOS ARGENTINA S.A. | M32: 45771 | N32: 4150300 | P32: =IF(ISBLANK(N32), "", VLOOKUP(D32&" "&E32, 'Info Tipo de Cambio y REM'!$A$24:$B$35, 2, FALSE)) -> 1325 | Q32: =IF(NOT(ISBLANK(N32)), N32 / P32, IF(NOT(ISBLANK(O32)), O32, "")) -> 3132.3019
A33: Clientes a cobrar | B33: =IF( A33="", "", IF( OR(A33="Santander-Galicia-Nación", A33="Bank Of America", A33="Transferwise", A33="Custodia Socios", A33="Cheques en cartera", A33="Caja"), "Activo Liquido", IF( OR(A33="Otras Inversiones", A33="Santander Inversiones"), "Mediano Plazo", IF( A33="Clientes a cobrar", "Clientes a cobrar", "DATO NO CARGADO" ) ) ) ) -> Clientes a cobrar | C33: =IF(K33="", "", IFERROR(VLOOKUP(K33, Clasificaciones!D:E, 2, FALSE), "DATO NO CARGADO")) -> Moreno Ocampo | D33: 03 mar | E33: 2025 | H33: =IF( A33="", "", IF( AND( F33="No", OR(G33="",G33>M33), M33<TODAY() ), "Vencido", "A término" ) ) -> A término | J33: Invoice 532 | K33: MORENO OCAMPO | M33: 45678 | O33: 250 | P33: =IF(ISBLANK(N33), "", VLOOKUP(D33&" "&E33, 'Info Tipo de Cambio y REM'!$A$24:$B$35, 2, FALSE)) | Q33: =IF(NOT(ISBLANK(N33)), N33 / P33, IF(NOT(ISBLANK(O33)), O33, "")) -> 250
A34: Clientes a cobrar | B34: =IF( A34="", "", IF( OR(A34="Santander-Galicia-Nación", A34="Bank Of America", A34="Transferwise", A34="Custodia Socios", A34="Cheques en cartera", A34="Caja"), "Activo Liquido", IF( OR(A34="Otras Inversiones", A34="Santander Inversiones"), "Mediano Plazo", IF( A34="Clientes a cobrar", "Clientes a cobrar", "DATO NO CARGADO" ) ) ) ) -> Clientes a cobrar | C34: =IF(K34="", "", IFERROR(VLOOKUP(K34, Clasificaciones!D:E, 2, FALSE), "DATO NO CARGADO")) -> Warner | D34: 03 mar | E34: 2025 | H34: =IF( A34="", "", IF( AND( F34="No", OR(G34="",G34>M34), M34<TODAY() ), "Vencido", "A término" ) ) -> A término | J34: Invoice 525 | K34: WARNER BROS | M34: 45726 | O34: 13450 | P34: =IF(ISBLANK(N34), "", VLOOKUP(D34&" "&E34, 'Info Tipo de Cambio y REM'!$A$24:$B$35, 2, FALSE)) | Q34: =IF(NOT(ISBLANK(N34)), N34 / P34, IF(NOT(ISBLANK(O34)), O34, "")) -> 13450
A35: Clientes a cobrar | B35: =IF( A35="", "", IF( OR(A35="Santander-Galicia-Nación", A35="Bank Of America", A35="Transferwise", A35="Custodia Socios", A35="Cheques en cartera", A35="Caja"), "Activo Liquido", IF( OR(A35="Otras Inversiones", A35="Santander Inversiones"), "Mediano Plazo", IF( A35="Clientes a cobrar", "Clientes a cobrar", "DATO NO CARGADO" ) ) ) ) -> Clientes a cobrar | C35: =IF(K35="", "", IFERROR(VLOOKUP(K35, Clasificaciones!D:E, 2, FALSE), "DATO NO CARGADO")) -> Warner | D35: 03 mar | E35: 2025 | H35: =IF( A35="", "", IF( AND( F35="No", OR(G35="",G35>M35), M35<TODAY() ), "Vencido", "A término" ) ) -> A término | J35: Invoice 534 | K35: WARNER BROS | M35: 45750 | O35: 13450 | P35: =IF(ISBLANK(N35), "", VLOOKUP(D35&" "&E35, 'Info Tipo de Cambio y REM'!$A$24:$B$35, 2, FALSE)) | Q35: =IF(NOT(ISBLANK(N35)), N35 / P35, IF(NOT(ISBLANK(O35)), O35, "")) -> 13450
A36: Clientes a cobrar | B36: =IF( A36="", "", IF( OR(A36="Santander-Galicia-Nación", A36="Bank Of America", A36="Transferwise", A36="Custodia Socios", A36="Cheques en cartera", A36="Caja"), "Activo Liquido", IF( OR(A36="Otras Inversiones", A36="Santander Inversiones"), "Mediano Plazo", IF( A36="Clientes a cobrar", "Clientes a cobrar", "DATO NO CARGADO" ) ) ) ) -> Clientes a cobrar | C36: =IF(K36="", "", IFERROR(VLOOKUP(K36, Clasificaciones!D:E, 2, FALSE), "DATO NO CARGADO")) -> Warner | D36: 03 mar | E36: 2025 | H36: =IF( A36="", "", IF( AND( F36="No", OR(G36="",G36>M36), M36<TODAY() ), "Vencido", "A término" ) ) -> A término | J36: Invoice 547 | K36: WARNER BROS | M36: 45782 | O36: 13450 | P36: =IF(ISBLANK(N36), "", VLOOKUP(D36&" "&E36, 'Info Tipo de Cambio y REM'!$A$24:$B$35, 2, FALSE)) | Q36: =IF(NOT(ISBLANK(N36)), N36 / P36, IF(NOT(ISBLANK(O36)), O36, "")) -> 13450
A37: Clientes a cobrar | B37: =IF( A37="", "", IF( OR(A37="Santander-Galicia-Nación", A37="Bank Of America", A37="Transferwise", A37="Custodia Socios", A37="Cheques en cartera", A37="Caja"), "Activo Liquido", IF( OR(A37="Otras Inversiones", A37="Santander Inversiones"), "Mediano Plazo", IF( A37="Clientes a cobrar", "Clientes a cobrar", "DATO NO CARGADO" ) ) ) ) -> Clientes a cobrar | C37: =IF(K37="", "", IFERROR(VLOOKUP(K37, Clasificaciones!D:E, 2, FALSE), "DATO NO CARGADO")) -> Warner | D37: 03 mar | E37: 2025 | H37: =IF( A37="", "", IF( AND( F37="No", OR(G37="",G37>M37), M37<TODAY() ), "Vencido", "A término" ) ) -> A término | J37: Invoice 553 | K37: WARNER BROS | M37: 45813 | O37: 13450 | P37: =IF(ISBLANK(N37), "", VLOOKUP(D37&" "&E37, 'Info Tipo de Cambio y REM'!$A$24:$B$35, 2, FALSE)) | Q37: =IF(NOT(ISBLANK(N37)), N37 / P37, IF(NOT(ISBLANK(O37)), O37, "")) -> 13450
A38: Clientes a cobrar | B38: =IF( A38="", "", IF( OR(A38="Santander-Galicia-Nación", A38="Bank Of America", A38="Transferwise", A38="Custodia Socios", A38="Cheques en cartera", A38="Caja"), "Activo Liquido", IF( OR(A38="Otras Inversiones", A38="Santander Inversiones"), "Mediano Plazo", IF( A38="Clientes a cobrar", "Clientes a cobrar", "DATO NO CARGADO" ) ) ) ) -> Clientes a cobrar | C38: =IF(K38="", "", IFERROR(VLOOKUP(K38, Clasificaciones!D:E, 2, FALSE), "DATO NO CARGADO")) -> Vertical Media | D38: 03 mar | E38: 2025 | H38: =IF( A38="", "", IF( AND( F38="No", OR(G38="",G38>M38), M38<TODAY() ), "Vencido", "A término" ) ) -> A término | J38: Invoice 560 | K38: VERTICAL MEDIA | M38: 45757 | O38: 1750 | P38: =IF(ISBLANK(N38), "", VLOOKUP(D38&" "&E38, 'Info Tipo de Cambio y REM'!$A$24:$B$35, 2, FALSE)) | Q38: =IF(NOT(ISBLANK(N38)), N38 / P38, IF(NOT(ISBLANK(O38)), O38, "")) -> 1750
A39: Santander-Galicia-Nación | B39: =IF( A39="", "", IF( OR(A39="Santander-Galicia-Nación", A39="Bank Of America", A39="Transferwise", A39="Custodia Socios", A39="Cheques en cartera", A39="Caja"), "Activo Liquido", IF( OR(A39="Otras Inversiones", A39="Santander Inversiones"), "Mediano Plazo", IF( A39="Clientes a cobrar", "Clientes a cobrar", "DATO NO CARGADO" ) ) ) ) -> Activo Liquido | C39: =IF(K39="", "", IFERROR(VLOOKUP(K39, Clasificaciones!D:E, 2, FALSE), "DATO NO CARGADO")) | D39: 04 abr | E39: 2025 | H39: =IF( A39="", "", IF( AND( F39="No", OR(G39="",G39>M39), M39<TODAY() ), "Vencido", "A término" ) ) -> A término | N39: 5365042 | P39: =IF(ISBLANK(N39), "", VLOOKUP(D39&" "&E39, 'Info Tipo de Cambio y REM'!$A$24:$B$35, 2, FALSE)) -> 1185 | Q39: =IF(NOT(ISBLANK(N39)), N39 / P39, IF(NOT(ISBLANK(O39)), O39, "")) -> 4527.4616
A40: Bank Of America | B40: =IF( A40="", "", IF( OR(A40="Santander-Galicia-Nación", A40="Bank Of America", A40="Transferwise", A40="Custodia Socios", A40="Cheques en cartera", A40="Caja"), "Activo Liquido", IF( OR(A40="Otras Inversiones", A40="Santander Inversiones"), "Mediano Plazo", IF( A40="Clientes a cobrar", "Clientes a cobrar", "DATO NO CARGADO" ) ) ) ) -> Activo Liquido | C40: =IF(K40="", "", IFERROR(VLOOKUP(K40, Clasificaciones!D:E, 2, FALSE), "DATO NO CARGADO")) | D40: 04 abr | E40: 2025 | H40: =IF( A40="", "", IF( AND( F40="No", OR(G40="",G40>M40), M40<TODAY() ), "Vencido", "A término" ) ) -> A término | O40: -27709 | P40: =IF(ISBLANK(N40), "", VLOOKUP(D40&" "&E40, 'Info Tipo de Cambio y REM'!$A$24:$B$35, 2, FALSE)) | Q40: =IF(NOT(ISBLANK(N40)), N40 / P40, IF(NOT(ISBLANK(O40)), O40, "")) -> -27709
...

Sheet ACTIVO BACK UP 5-9 previo cambi
A1: Concepto/Banco | B1: Tipo de Activo | C1: Cliente | D1: Mes | E1: Año | F1: Cobrado/No Cobrado AL CIERRE | G1: Fecha de pago | H1: Fecha Facturación | I1: Nro de Factura/Comprobante | J1: Razón Social/Cliente | K1: Detalle | L1: Fecha de vencimiento | M1: Moneda original ARS | N1: Moneda original USD | O1: Cotización | P1: Monto Total USD
A2: Santander-Galicia-Nación | B2: =IF( A2="", "", IF( OR(A2="Santander-Galicia-Nación", A2="Bank Of America", A2="Transferwise", A2="Custodia Socios", A2="Cheques en cartera", A2="Caja"), "Activo Liquido", IF( OR(A2="Otras Inversiones", A2="Santander Inversiones"), "Mediano Plazo", IF( A2="Clientes a cobrar", "Clientes a cobrar", "DATO NO CARGADO" ) ) ) ) -> Activo Liquido | C2: =IF(J2="", "", IFERROR(VLOOKUP(J2, Clasificaciones!D:E, 2, FALSE), "DATO NO CARGADO")) | D2: 01 ene | E2: 2025 | M2: 8217613 | O2: =IF(ISBLANK(M2), "", VLOOKUP(D2, 'Info Tipo de Cambio y REM'!$A$24:$B$35, 2, FALSE)) -> #N/A | P2: =IF(NOT(ISBLANK(M2)), M2 / O2, IF(NOT(ISBLANK(N2)), N2, "")) -> #N/A
A3: Bank Of America | B3: =IF( A3="", "", IF( OR(A3="Santander-Galicia-Nación", A3="Bank Of America", A3="Transferwise", A3="Custodia Socios", A3="Cheques en cartera", A3="Caja"), "Activo Liquido", IF( OR(A3="Otras Inversiones", A3="Santander Inversiones"), "Mediano Plazo", IF( A3="Clientes a cobrar", "Clientes a cobrar", "DATO NO CARGADO" ) ) ) ) -> Activo Liquido | C3: =IF(J3="", "", IFERROR(VLOOKUP(J3, Clasificaciones!D:E, 2, FALSE), "DATO NO CARGADO")) | D3: 01 ene | E3: 2025 | N3: -2840 | O3: =IF(ISBLANK(M3), "", VLOOKUP(D3, 'Info Tipo de Cambio y REM'!$A$24:$B$35, 2, FALSE)) | P3: =IF(NOT(ISBLANK(M3)), M3 / O3, IF(NOT(ISBLANK(N3)), N3, "")) -> -2840
A4: Transferwise | B4: =IF( A4="", "", IF( OR(A4="Santander-Galicia-Nación", A4="Bank Of America", A4="Transferwise", A4="Custodia Socios", A4="Cheques en cartera", A4="Caja"), "Activo Liquido", IF( OR(A4="Otras Inversiones", A4="Santander Inversiones"), "Mediano Plazo", IF( A4="Clientes a cobrar", "Clientes a cobrar", "DATO NO CARGADO" ) ) ) ) -> Activo Liquido | C4: =IF(J4="", "", IFERROR(VLOOKUP(J4, Clasificaciones!D:E, 2, FALSE), "DATO NO CARGADO")) | D4: 01 ene | E4: 2025 | N4: 230 | O4: =IF(ISBLANK(M4), "", VLOOKUP(D4, 'Info Tipo de Cambio y REM'!$A$24:$B$35, 2, FALSE)) | P4: =IF(NOT(ISBLANK(M4)), M4 / O4, IF(NOT(ISBLANK(N4)), N4, "")) -> 230
